2025-04-17 08:52:37,365 - INFO - Start polling
2025-04-17 08:52:37,563 - INFO - Run polling for bot @pembacabukurajin_bot id=8130009494 - 'sipembacabuku'
2025-04-17 08:52:49,522 - INFO - Update id=384434696 is handled. Duration 1529 ms by bot id=8130009494
2025-04-17 08:53:03,021 - INFO - Update id=384434697 is handled. Duration 1139 ms by bot id=8130009494
2025-04-17 08:53:05,306 - INFO - Update id=384434698 is not handled. Duration 0 ms by bot id=8130009494
2025-04-17 08:53:05,306 - ERROR - Cause exception while process update id=384434698 by bot id=8130009494
NameError: name 'pending_confess_path' is not defined
Traceback (most recent call last):
  File "C:\Users\Administrator\AppData\Local\Programs\Python\Python38\lib\site-packages\aiogram\dispatcher\dispatcher.py", line 309, in _process_update
    response = await self.feed_update(bot, update, **kwargs)
  File "C:\Users\Administrator\AppData\Local\Programs\Python\Python38\lib\site-packages\aiogram\dispatcher\dispatcher.py", line 158, in feed_update
    response = await self.update.wrap_outer_middleware(
  File "C:\Users\Administrator\AppData\Local\Programs\Python\Python38\lib\site-packages\aiogram\dispatcher\middlewares\error.py", line 25, in __call__
    return await handler(event, data)
  File "C:\Users\Administrator\AppData\Local\Programs\Python\Python38\lib\site-packages\aiogram\dispatcher\middlewares\user_context.py", line 56, in __call__
    return await handler(event, data)
  File "C:\Users\Administrator\AppData\Local\Programs\Python\Python38\lib\site-packages\aiogram\fsm\middleware.py", line 42, in __call__
    return await handler(event, data)
  File "C:\Users\Administrator\Desktop\bot_confess\db\users_db.py", line 124, in __call__
    return await handler(event, data)
  File "C:\Users\Administrator\AppData\Local\Programs\Python\Python38\lib\site-packages\aiogram\dispatcher\event\telegram.py", line 121, in trigger
    return await wrapped_inner(event, kwargs)
  File "C:\Users\Administrator\AppData\Local\Programs\Python\Python38\lib\site-packages\aiogram\dispatcher\event\handler.py", line 43, in call
    return await wrapped()
  File "C:\Users\Administrator\AppData\Local\Programs\Python\Python38\lib\site-packages\aiogram\dispatcher\dispatcher.py", line 276, in _listen_update
    return await self.propagate_event(update_type=update_type, event=event, **kwargs)
  File "C:\Users\Administrator\AppData\Local\Programs\Python\Python38\lib\site-packages\aiogram\dispatcher\router.py", line 146, in propagate_event
    return await observer.wrap_outer_middleware(_wrapped, event=event, data=kwargs)
  File "C:\Users\Administrator\AppData\Local\Programs\Python\Python38\lib\site-packages\aiogram\dispatcher\router.py", line 141, in _wrapped
    return await self._propagate_event(
  File "C:\Users\Administrator\AppData\Local\Programs\Python\Python38\lib\site-packages\aiogram\dispatcher\router.py", line 174, in _propagate_event
    response = await router.propagate_event(update_type=update_type, event=event, **kwargs)
  File "C:\Users\Administrator\AppData\Local\Programs\Python\Python38\lib\site-packages\aiogram\dispatcher\router.py", line 146, in propagate_event
    return await observer.wrap_outer_middleware(_wrapped, event=event, data=kwargs)
  File "C:\Users\Administrator\AppData\Local\Programs\Python\Python38\lib\site-packages\aiogram\dispatcher\router.py", line 141, in _wrapped
    return await self._propagate_event(
  File "C:\Users\Administrator\AppData\Local\Programs\Python\Python38\lib\site-packages\aiogram\dispatcher\router.py", line 166, in _propagate_event
    response = await observer.trigger(event, **kwargs)
  File "C:\Users\Administrator\AppData\Local\Programs\Python\Python38\lib\site-packages\aiogram\dispatcher\event\telegram.py", line 121, in trigger
    return await wrapped_inner(event, kwargs)
  File "C:\Users\Administrator\AppData\Local\Programs\Python\Python38\lib\site-packages\aiogram\dispatcher\event\handler.py", line 43, in call
    return await wrapped()
  File "C:\Users\Administrator\Desktop\bot_confess\handlers\start_handler.py", line 37, in start_handler
    pending_confess = get_pending_confess(message.from_user.id)
  File "C:\Users\Administrator\Desktop\bot_confess\handlers\start_handler.py", line 17, in get_pending_confess
    conn = sqlite3.connect(pending_confess_path)
NameError: name 'pending_confess_path' is not defined
2025-04-17 09:56:19,531 - ERROR - Failed to fetch updates - TelegramNetworkError: HTTP Client says - Request timeout error
2025-04-17 09:56:19,531 - WARNING - Sleep for 1.000000 seconds and try again... (tryings = 0, bot id = 8130009494)
2025-04-17 09:56:20,538 - ERROR - Failed to fetch updates - TelegramNetworkError: HTTP Client says - ClientConnectorDNSError: Cannot connect to host api.telegram.org:443 ssl:default [getaddrinfo failed]
2025-04-17 09:56:29,535 - WARNING - Sleep for 1.258917 seconds and try again... (tryings = 1, bot id = 8130009494)
2025-04-17 09:56:41,456 - INFO - Connection established (tryings = 2, bot id = 8130009494)
